Workbook

Sheet Tổng quan
A1: Kế hoạch đồ án – Nhóm G5 – Đề tài #5: Cổng thông tin phòng khám & y tế từ xa (Telemedicine)
A2: INT1313 Cơ sở dữ liệu – Nhóm tổ 06 – HK1 2026-2027 – GV: Lê Hà Thanh
A4: Ngày bắt đầu Tuần 1 | C4: ← nhập ngày (ô vàng); để trống thì cột ngày ở sheet Kế hoạch bỏ trống
A6: Thành viên
A7: Gọi tắt | B7: Họ tên | C7: MSSV | D7: Email | E7: Vai trò chung | F7: Mảng nghiệp vụ sở hữu (end-to-end)
A8: Khôi | B8: Lê Ngọc Khôi | C8: B24DTCN061 | D8: khoiln.b24dtcn061@stu.ptit.edu.vn | E8: Trưởng nhóm: điều phối, báo cáo tiến độ tuần, tổng hợp tài liệu báo cáo, khung ứng dụng Flask, slide | F8: B. Bệnh nhân & Lịch hẹn (đặt lịch, khám trực tiếp / tư vấn từ xa, chuyển chuyên khoa, thanh toán)
A9: Hữu Khoa | B9: Đặng Hữu Khoa | C9: K24DTCN558 | D9: khoadh.k24dtcn558@stu.ptit.edu.vn | E9: Phụ trách mô hình dữ liệu: ERD tổng (ký hiệu Elmasri), ánh xạ lược đồ, từ điển dữ liệu, script DDL tổng | F9: A. Nhân viên y tế & Lịch làm việc (EER phân lớp Bác sĩ đa khoa / chuyên khoa)
A10: Đăng Khoa | B10: Nguyễn Đăng Khoa | C10: K24DTCN398 | D10: khoand.k24dtcn398@stu.ptit.edu.vn | E10: Phụ trách kiểm thử & bảo mật: review chuẩn hóa, dữ liệu mẫu, test ràng buộc, kiểm thử hiệu năng, RBAC | F10: C. Hồ sơ bệnh án & Đơn thuốc điện tử (lần khám, chẩn đoán, đơn thuốc, dị ứng)
A11: Nguyên tắc: mỗi người tự làm mảng của mình từ ERD → ánh xạ → chuẩn hóa → DDL → trigger/view → 4 truy vấn → màn hình UI, nên ai cũng tự bảo vệ được phần SQL của mình. Vai trò chung là phần tổng hợp/kiểm tra chéo, không phải làm thay.
A13: Giai đoạn & trọng số (theo đề cương)
A14: Mã | B14: Giai đoạn | C14: Tuần | D14: Sản phẩm phải nộp | E14: Tiêu chí / Trọng số | F14: Phiên bản báo cáo
A15: GĐ0 | B15: Khảo sát & Xác lập yêu cầu | C15: 1–2 | D15: Database Requirement Specification: mục tiêu, phạm vi, quy tắc nghiệp vụ | E15: Nền cho GĐ1 | F15: v1
A16: GĐ1 | B16: Thiết kế khái niệm | C16: 3–4 | D16: Phát biểu vấn đề, quy tắc nghiệp vụ, sơ đồ ER/EER toàn diện | E16: Thiết kế – 20% | F16: v2.1
A17: GĐ2 | B17: Thiết kế logic & chuẩn hóa | C17: 5–8 | D17: Ánh xạ lược đồ quan hệ, khóa ngoại, chứng minh 3NF/BCNF, từ điển dữ liệu | E17: Phân tích – 20% | F17: v2.2
A18: GĐ3 | B18: Cài đặt & truy vấn | C18: 9–10 | D18: DDL, dữ liệu mẫu (DML), 10+ truy vấn phức tạp, ≥2 trigger/view, test, RBAC | E18: Cài đặt – 30% | F18: v3
A19: GĐ4 | B19: Tích hợp ứng dụng & bảo vệ | C19: 11–12 | D19: UI + backend Flask kết nối CSDL, thuyết trình, đánh giá chéo | E19: Làm việc nhóm – 30% | F19: v4 (bản cuối)
A21: Công nghệ đề xuất
A22: DBMS | B22: PostgreSQL 16 (CHECK, trigger PL/pgSQL, EXCLUDE constraint chống trùng lịch, GRANT/REVOKE theo role)
A23: Vẽ ERD | B23: draw.io (ký hiệu Chen/Elmasri như giáo trình) – lưu file .drawio trong repo
A24: Backend / UI | B24: Python Flask + psycopg + Jinja2 (HTML đơn giản)
A25: Quản lý mã | B25: GitHub repo chung: /docs, /erd, /sql (schema, seed, queries, tests, rbac), /app
A26: Liên lạc | B26: Nhóm Zalo/Messenger + họp online 1 buổi/tuần (khoảng 45 phút)
A28: Chú thích
A29: • Ô nền vàng = ô cần nhập (ngày bắt đầu, trạng thái, % hoàn thành, ghi chú).
A30: • Sheet 'Kế hoạch': cập nhật cột Trạng thái và % mỗi tuần trước buổi họp. Sheet 'Thống kê' tự tính tiến độ.
A31: • Sheet 'Báo cáo tuần': mỗi thành viên ghi 1 dòng/tuần (dòng 1 là ví dụ mẫu) – dùng làm bằng chứng cho đánh giá chéo.
A32: • Có thể đổi người phụ trách giữa các mảng nếu cả nhóm đồng ý; sửa ở sheet 'Tổng quan' và 'Kế hoạch'.

Sheet Kế hoạch
A1: Kế hoạch công việc theo tuần
A2: Cập nhật cột Trạng thái / % hoàn thành / Ghi chú (ô vàng) mỗi tuần.
A4: Mã | B4: Tuần | C4: Từ ngày | D4: Đến ngày | E4: Giai đoạn | F4: Công việc | G4: Người phụ trách | H4: Người review | I4: Sản phẩm / Kết quả | J4: Trạng thái | K4: % hoàn thành | L4: Ghi chú
A5: T01 | B5: 1 | C5: =IF('Tổng quan'!$B$4="","",'Tổng quan'!$B$4+(B5-1)*7) | D5: =IF('Tổng quan'!$B$4="","",C5+6) | E5: GĐ0 | F5: Họp khởi động: thống nhất vai trò, mảng nghiệp vụ, lịch họp, kênh liên lạc | G5: Cả nhóm | H5: Cả nhóm | I5: Biên bản họp #1 | J5: Chưa bắt đầu | K5: 0
A6: T02 | B6: 1 | C6: =IF('Tổng quan'!$B$4="","",'Tổng quan'!$B$4+(B6-1)*7) | D6: =IF('Tổng quan'!$B$4="","",C6+6) | E6: GĐ0 | F6: Tạo repo GitHub + cấu trúc thư mục; cài PostgreSQL & draw.io trên máy cả nhóm | G6: Khôi | H6: Cả nhóm | I6: Repo + README hướng dẫn cài đặt | J6: Đang làm | K6: 0.8 | L6: Repo + cấu trúc thư mục + README xong; máy Khôi đã cài PG16 + draw.io. Chờ Hữu Khoa, Đăng Khoa cài theo README và báo lại
A7: T03 | B7: 1 | C7: =IF('Tổng quan'!$B$4="","",'Tổng quan'!$B$4+(B7-1)*7) | D7: =IF('Tổng quan'!$B$4="","",C7+6) | E7: GĐ0 | F7: Khảo sát quy trình đặt lịch, khám trực tiếp, tư vấn từ xa, thanh toán (biểu mẫu, ứng dụng thực tế) | G7: Khôi | H7: Đăng Khoa | I7: Ghi chú khảo sát mảng B | J7: Hoàn thành | K7: 1 | L7: docs/khao-sat/T03_KhaoSat_MangB.md – viết lại theo ISO/IEC/IEEE 29148, bổ sung quy định khám từ xa (19/10); chờ Đăng Khoa review
A8: T04 | B8: 1 | C8: =IF('Tổng quan'!$B$4="","",'Tổng quan'!$B$4+(B8-1)*7) | D8: =IF('Tổng quan'!$B$4="","",C8+6) | E8: GĐ0 | F8: Khảo sát tổ chức nhân sự y tế, chuyên khoa, chứng chỉ hành nghề, ca làm việc | G8: Hữu Khoa | H8: Khôi | I8: Ghi chú khảo sát mảng A | J8: Hoàn thành | K8: 1 | L8: docs/khao-sat/T04_KhaoSat_MangA.md – Khôi soạn 19/10 theo ISO/IEC/IEEE 29148; chờ Hữu Khoa xác nhận
A9: T05 | B9: 1 | C9: =IF('Tổng quan'!$B$4="","",'Tổng quan'!$B$4+(B9-1)*7) | D9: =IF('Tổng quan'!$B$4="","",C9+6) | E9: GĐ0 | F9: Khảo sát hồ sơ bệnh án, chẩn đoán (ICD-10), đơn thuốc điện tử, dị ứng thuốc | G9: Đăng Khoa | H9: Hữu Khoa | I9: Ghi chú khảo sát mảng C | J9: Hoàn thành | K9: 1 | L9: docs/khao-sat/T05_KhaoSat_MangC.md – viết lại theo ISO/IEC/IEEE 29148, bổ sung quy định kê đơn, bệnh án điện tử (19/10); chờ Hữu Khoa review
A10: T06 | B10: 2 | C10: =IF('Tổng quan'!$B$4="","",'Tổng quan'!$B$4+(B10-1)*7) | D10: =IF('Tổng quan'!$B$4="","",C10+6) | E10: GĐ0 | F10: Viết mục 1 + 1.1: giới thiệu, phạm vi, mục tiêu hệ thống, tác nhân (theo ISO/IEC/IEEE 29148) | G10: Khôi | H10: Hữu Khoa | I10: Báo cáo mục 1, 1.1 | J10: Hoàn thành | K10: 1 | L10: Đã điền mục 1, 1.1 vào docs/INT1313_TX_G5_DeTai05_Telemedicine_v0.docx – chờ Hữu Khoa review
A11: T07 | B11: 2 | C11: =IF('Tổng quan'!$B$4="","",'Tổng quan'!$B$4+(B11-1)*7) | D11: =IF('Tổng quan'!$B$4="","",C11+6) | E11: GĐ0 | F11: Viết quy tắc nghiệp vụ BR-A01… cho mảng A (đánh số, có thể kiểm chứng) | G11: Hữu Khoa | H11: Đăng Khoa | I11: Danh sách BR mảng A | J11: Hoàn thành | K11: 1 | L11: docs/br/T07_BR_MangA.md – BR-A01…A08 theo Business Rules Manifesto/SBVR, khớp báo cáo v2.1 (19/10); chờ Đăng Khoa review
A12: T08 | B12: 2 | C12: =IF('Tổng quan'!$B$4="","",'Tổng quan'!$B$4+(B12-1)*7) | D12: =IF('Tổng quan'!$B$4="","",C12+6) | E12: GĐ0 | F12: Viết quy tắc nghiệp vụ BR-B01… cho mảng B | G12: Khôi | H12: Hữu Khoa | I12: Danh sách BR mảng B | J12: Hoàn thành | K12: 1 | L12: docs/br/T08_BR_MangB.md – thu gọn còn BR-B01…B07, theo Business Rules Manifesto/SBVR (19/10); chờ Hữu Khoa review
A13: T09 | B13: 2 | C13: =IF('Tổng quan'!$B$4="","",'Tổng quan'!$B$4+(B13-1)*7) | D13: =IF('Tổng quan'!$B$4="","",C13+6) | E13: GĐ0 | F13: Viết quy tắc nghiệp vụ BR-C01… cho mảng C | G13: Đăng Khoa | H13: Khôi | I13: Danh sách BR mảng C | J13: Hoàn thành | K13: 1 | L13: docs/br/T09_BR_MangC.md – BR-C01…C05 theo Business Rules Manifesto/SBVR; Khôi đã review 19/10
A14: T10 | B14: 2 | C14: =IF('Tổng quan'!$B$4="","",'Tổng quan'!$B$4+(B14-1)*7) | D14: =IF('Tổng quan'!$B$4="","",C14+6) | E14: GĐ0 | F14: Tổng hợp mục 1.2, review chéo, nộp báo cáo v1 + báo cáo tiến độ | G14: Khôi | H14: Cả nhóm | I14: Báo cáo v1 | J14: Hoàn thành | K14: 1 | L14: Đã nộp báo cáo v1 (mục 1, 1.1, 1.2) và báo cáo tiến độ. Nội dung v1 được nối tiếp trong docs/INT1313_TX_G5_DeTai05_Telemedicine_v2.1.docx; bản v1 xem lịch sử git (commit a2902ac)
A15: T11 | B15: 3 | C15: =IF('Tổng quan'!$B$4="","",'Tổng quan'!$B$4+(B15-1)*7) | D15: =IF('Tổng quan'!$B$4="","",C15+6) | E15: GĐ1 | F15: Vẽ EER mảng A: BAC_SI → {ĐA_KHOA, CHUYÊN_KHOA}; ràng buộc disjoint/total; chuyên khoa, ca làm việc | G15: Hữu Khoa | H15: Đăng Khoa | I15: ERD mảng A (.drawio) | J15: Hoàn thành | K15: 1 | L15: erd/A.drawio, erd/A.png – Khôi vẽ 19/10 theo T04, T07; chờ Hữu Khoa xác nhận tên liên kết THUỘC, XẾP_CA
A16: T12 | B16: 3 | C16: =IF('Tổng quan'!$B$4="","",'Tổng quan'!$B$4+(B16-1)*7) | D16: =IF('Tổng quan'!$B$4="","",C16+6) | E16: GĐ1 | F16: Vẽ ER/EER mảng B: BENH_NHAN, LICH_HEN → {KHÁM_TRỰC_TIẾP, TƯ_VẤN_TỪ_XA}, giấy chuyển chuyên khoa, hóa đơn | G16: Khôi | H16: Hữu Khoa | I16: ERD mảng B | J16: Hoàn thành | K16: 1 | L16: erd/B.drawio, erd/B.png – Chen/Elmasri; bỏ HOA_DON, phí khám là thuộc tính lịch hẹn (19/10); chờ Hữu Khoa review
A17: T13 | B17: 3 | C17: =IF('Tổng quan'!$B$4="","",'Tổng quan'!$B$4+(B17-1)*7) | D17: =IF('Tổng quan'!$B$4="","",C17+6) | E17: GĐ1 | F17: Vẽ ER mảng C: HO_SO_BENH_AN, LAN_KHAM, CHAN_DOAN, DON_THUOC, THUOC, DI_UNG | G17: Đăng Khoa | H17: Khôi | I17: ERD mảng C | J17: Hoàn thành | K17: 1 | L17: erd/C.drawio, erd/C.png – Chen/Elmasri; bỏ HO_SO_BENH_AN, chi tiết đơn là liên kết M:N KÊ (19/10); Khôi đã review
... A21: T17 | B21: 4 | C21: =IF('Tổng quan'!$B$4="","",'Tổng quan'!$B$4+(B21-1)*7) | D21: =IF('Tổng quan'!$B$4="","",C21+6) | E21: GĐ1 | F21: Review, nộp báo cáo v2.1 + báo cáo tiến độ | G21: Khôi | H21: Cả nhóm | I21: Báo cáo v2.1 | J21: Hoàn thành | K21: 1 | L21: docs/INT1313_TX_G5_DeTai05_Telemedicine_v2.1.docx – mục Giới thiệu tóm tắt, 1, 1.2, 2, 2.1 hoàn chỉnh, có ERD tổng; đã nộp 21/10/2026
A22: T18 | B22: 5 | C22: =IF('Tổng quan'!$B$4="","",'Tổng quan'!$B$4+(B22-1)*7) | D22: =IF('Tổng quan'!$B$4="","",C22+6) | E22: GĐ2 | F22: Chốt quy ước đặt tên bảng/cột, kiểu dữ liệu chung (mã, tiền, ngày giờ, trạng thái) | G22: Hữu Khoa | H22: Cả nhóm | I22: Tài liệu quy ước | J22: Chưa bắt đầu | K22: 0
A23: T19 | B23: 5 | C23: =IF('Tổng quan'!$B$4="","",'Tổng quan'!$B$4+(B23-1)*7) | D23: =IF('Tổng quan'!$B$4="","",C23+6) | E23: GĐ2 | F23: Ánh xạ mảng A (thuật toán Elmasri bước 1–7) + chọn phương án bước 8 (8A/8B/8C/8D) cho phân lớp, có lý giải | G23: Hữu Khoa | H23: Đăng Khoa | I23: Lược đồ quan hệ mảng A | J23: Chưa bắt đầu | K23: 0
A24: T20 | B24: 5 | C24: =IF('Tổng quan'!$B$4="","",'Tổng quan'!$B$4+(B24-1)*7) | D24: =IF('Tổng quan'!$B$4="","",C24+6) | E24: GĐ2 | F24: Ánh xạ mảng B sang lược đồ quan hệ, xác định PK/FK | G24: Khôi | H24: Hữu Khoa | I24: Lược đồ quan hệ mảng B | J24: Hoàn thành | K24: 1 | L24: docs/5_anh-xa/T20_AnhXa_MangB.md – 4 bảng BENH_NHAN, GIAY_CHUYEN_KHOA, LICH_HEN, TAI_KHOAN; PK/FK theo Elmasri bước 1–8, LICH_HEN chọn 8C (27/10); chờ Hữu Khoa review, xác nhận 8A cho BAC_SI (T19)
A25: T21 | B25: 5 | C25: =IF('Tổng quan'!$B$4="","",'Tổng quan'!$B$4+(B25-1)*7) | D25: =IF('Tổng quan'!$B$4="","",C25+6) | E25: GĐ2 | F25: Ánh xạ mảng C sang lược đồ quan hệ, xác định PK/FK | G25: Đăng Khoa | H25: Khôi | I25: Lược đồ quan hệ mảng C | J25: Chưa bắt đầu | K25: 0
A26: T22 | B26: 6 | C26: =IF('Tổng quan'!$B$4="","",'Tổng quan'!$B$4+(B26-1)*7) | D26: =IF('Tổng quan'!$B$4="","",C26+6) | E26: GĐ2 | F26: Chuẩn bị khuôn trình bày chứng minh chuẩn hóa (FD, khóa, 1NF→2NF→3NF→BCNF) | G26: Đăng Khoa | H26: Khôi | I26: Mẫu chứng minh | J26: Chưa bắt đầu | K26: 0
A27: T23 | B27: 6 | C27: =IF('Tổng quan'!$B$4="","",'Tổng quan'!$B$4+(B27-1)*7) | D27: =IF('Tổng quan'!$B$4="","",C27+6) | E27: GĐ2 | F27: Liệt kê phụ thuộc hàm (FD) và khóa ứng viên cho các bảng mảng A | G27: Hữu Khoa | H27: Đăng Khoa | I27: FD mảng A | J27: Chưa bắt đầu | K27: 0
A28: T24 | B28: 6 | C28: =IF('Tổng quan'!$B$4="","",'Tổng quan'!$B$4+(B28-1)*7) | D28: =IF('Tổng quan'!$B$4="","",C28+6) | E28: GĐ2 | F28: Liệt kê FD và khóa ứng viên cho các bảng mảng B | G28: Khôi | H28: Đăng Khoa | I28: FD mảng B | J28: Hoàn thành | K28: 1 | L28: docs/6_chuan-hoa/T24_FD_MangB.md – FD (phủ tối thiểu), FD đã loại kèm lý do, khóa ứng viên 4 bảng; BENH_NHAN có 2 khóa {ma_bn}, {sdt} (27/10); chờ Đăng Khoa review
A29: T25 | B29: 6 | C29: =IF('Tổng quan'!$B$4="","",'Tổng quan'!$B$4+(B29-1)*7) | D29: =IF('Tổng quan'!$B$4="","",C29+6) | E29: GĐ2 | F29: Liệt kê FD và khóa ứng viên cho các bảng mảng C | G29: Đăng Khoa | H29: Hữu Khoa | I29: FD mảng C | J29: Chưa bắt đầu | K29: 0
A30: T26 | B30: 7 | C30: =IF('Tổng quan'!$B$4="","",'Tổng quan'!$B$4+(B30-1)*7) | D30: =IF('Tổng quan'!$B$4="","",C30+6) | E30: GĐ2 | F30: Chứng minh 3NF/BCNF mảng A, tách bảng nếu vi phạm | G30: Hữu Khoa | H30: Đăng Khoa | I30: Mục 2.3 – phần A | J30: Chưa bắt đầu | K30: 0
A31: T27 | B31: 7 | C31: =IF('Tổng quan'!$B$4="","",'Tổng quan'!$B$4+(B31-1)*7) | D31: =IF('Tổng quan'!$B$4="","",C31+6) | E31: GĐ2 | F31: Chứng minh 3NF/BCNF mảng B, tách bảng nếu vi phạm | G31: Khôi | H31: Đăng Khoa | I31: Mục 2.3 – phần B | J31: Hoàn thành | K31: 1 | L31: docs/6_chuan-hoa/T27_ChuanHoa_MangB.md – 4 bảng đạt BCNF, không tách; lập luận riêng cho FD có điều kiện (cột UNIQUE cho phép NULL); vai_tro trùng loai_nv chuyển T30 (27/10); chờ Đăng Khoa review
A32: T28 | B32: 7 | C32: =IF('Tổng quan'!$B$4="","",'Tổng quan'!$B$4+(B32-1)*7) | D32: =IF('Tổng quan'!$B$4="","",C32+6) | E32: GĐ2 | F32: Chứng minh 3NF/BCNF mảng C, tách bảng nếu vi phạm | G32: Đăng Khoa | H32: Hữu Khoa | I32: Mục 2.3 – phần C | J32: Chưa bắt đầu | K32: 0
A33: T29 | B33: 7 | C33: =IF('Tổng quan'!$B$4="","",'Tổng quan'!$B$4+(B33-1)*7) | D33: =IF('Tổng quan'!$B$4="","",C33+6) | E33: GĐ2 | F33: Từ điển dữ liệu (mục 3, theo ISO/IEC 11179): mỗi người điền bảng của mình, Hữu Khoa gộp | G33: Hữu Khoa | H33: Cả nhóm | I33: Mục 3 | J33: Chưa bắt đầu | K33: 0
A34: T30 | B34: 8 | C34: =IF('Tổng quan'!$B$4="","",'Tổng quan'!$B$4+(B34-1)*7) | D34: =IF('Tổng quan'!$B$4="","",C34+6) | E34: GĐ2 | F34: Review chéo toàn bộ mục 2.2, 2.3, 3; sửa ERD nếu chuẩn hóa làm thay đổi thiết kế | G34: Đăng Khoa | H34: Cả nhóm | I34: Danh sách lỗi đã sửa | J34: Đang làm | K34: 0.3 | L34: docs/6_chuan-hoa/T30_ReviewCheo.md – đã rà phần B (Khôi, 27/10): L01 sửa T20 (FK kép giấy – bệnh nhân); L02–L04 diễn giải trigger đã xác nhận, ghi vào T08 mục 5; ERD B không phải sửa; chờ A, C (T19, T21, T26, T28), mục 3 (T29); C1 vai_tro/loai_nv chờ nhóm họp
A35: T31 | B35: 8 | C35: =IF('Tổng quan'!$B$4="","",'Tổng quan'!$B$4+(B35-1)*7) | D35: =IF('Tổng quan'!$B$4="","",C35+6) | E35: GĐ2 | F35: Hoàn thiện, nộp báo cáo v2.2 + báo cáo tiến độ | G35: Khôi | H35: Cả nhóm | I35: Báo cáo v2.2 | J35: Đang làm | K35: 0.3 | L35: docs/INT1313_TX_G5_DeTai05_Telemedicine_v2.2.docx (nháp, 27/10) – trang bìa v2.2; đã điền phần B mục 2.2 (bước ánh xạ, 8C cho LICH_HEN, lược đồ, khóa ngoại), 2.3 (FD, khóa, chứng minh BCNF), 3 (4 bảng, miền giá trị); phần A, C để chữ xám chờ T19, T21, T23, T25, T26, T28, T29; còn Hình 2.2, review chéo, nộp
A36: T32 | B36: 9 | C36: =IF('Tổng quan'!$B$4="","",'Tổng quan'!$B$4+(B36-1)*7) | D36: =IF('Tổng quan'!$B$4="","",C36+6) | E36: GĐ3 | F36: DDL mảng A: bảng, PK/FK, NOT NULL, CHECK, UNIQUE, index | G36: Hữu Khoa | H36: Đăng Khoa | I36: sql/A_schema.sql | J36: Chưa bắt đầu | K36: 0
A37: T33 | B37: 9 | C37: =IF('Tổng quan'!$B$4="","",'Tổng quan'!$B$4+(B37-1)*7) | D37: =IF('Tổng quan'!$B$4="","",C37+6) | E37: GĐ3 | F37: DDL mảng B: bảng, ràng buộc, index (kể cả chống trùng lịch hẹn) | G37: Khôi | H37: Hữu Khoa | I37: sql/B_schema.sql | J37: Hoàn thành | K37: 1 | L37: sql/B_schema.sql – 4 bảng; CHECK hình thức (8C), hạn giấy 30 ngày, chủ tài khoản; FK kép (ma_giay, ma_bn) cho BR-B03; EXCLUDE gist chống trùng lịch bác sĩ, bệnh nhân (BR-B02); 4 index. Đã chạy thử trên PG16 với bảng A giả lập (27/10). Giả định khóa A kiểu INTEGER, BAC_SI theo 8A – chờ T18, T32
A38: T34 | B38: 9 | C38: =IF('Tổng quan'!$B$4="","",'Tổng quan'!$B$4+(B38-1)*7) | D38: =IF('Tổng quan'!$B$4="","",C38+6) | E38: GĐ3 | F38: DDL mảng C: bảng, ràng buộc, index | G38: Đăng Khoa | H38: Khôi | I38: sql/C_schema.sql | J38: Chưa bắt đầu | K38: 0
A39: T35 | B39: 9 | C39: =IF('Tổng quan'!$B$4="","",'Tổng quan'!$B$4+(B39-1)*7) | D39: =IF('Tổng quan'!$B$4="","",C39+6) | E39: GĐ3 | F39: Gộp script schema.sql tổng, chạy lại từ đầu không lỗi | G39: Hữu Khoa | H39: Cả nhóm | I39: sql/schema.sql | J39: Chưa bắt đầu | K39: 0
A40: T36 | B40: 9 | C40: =IF('Tổng quan'!$B$4="","",'Tổng quan'!$B$4+(B40-1)*7) | D40: =IF('Tổng quan'!$B$4="","",C40+6) | E40: GĐ3 | F40: Trigger + view mảng A (vd: chặn ca làm việc chồng giờ; v_lich_truc_bac_si) | G40: Hữu Khoa | H40: Đăng Khoa | I40: sql/A_trigger_view.sql | J40: Chưa bắt đầu | K40: 0
A41: T37 | B41: 9 | C41: =IF('Tổng quan'!$B$4="","",'Tổng quan'!$B$4+(B41-1)*7) | D41: =IF('Tổng quan'!$B$4="","",C41+6) | E41: GĐ3 | F41: Trigger + view mảng B (vd: lịch hẹn phải nằm trong ca bác sĩ; v_lich_hen_hom_nay) | G41: Khôi | H41: Đăng Khoa | I41: sql/B_trigger_view.sql | J41: Hoàn thành | K41: 1 | L41: sql/B_trigger_view.sql – trg_lich_hen_hop_le (BR-B01 trong ca; BR-B03 giấy đúng chuyên khoa, còn hạn, miễn tái khám), trg_trang_thai_lich_hen (BR-B05), trg_tai_khoan_vai_tro (BR-B09), trg_tai_khoan_khong_xoa (BR-B10); view v_lich_hen_hom_nay. Chạy thử PG16 với bảng A giả lập: 17 ca vi phạm đều bị chặn (27/10). Giả định cột ca_lam_viec, bac_si_chuyen_khoa – chờ T32
A42: T38 | B42: 9 | C42: =IF('Tổng quan'!$B$4="","",'Tổng quan'!$B$4+(B42-1)*7) | D42: =IF('Tổng quan'!$B$4="","",C42+6) | E42: GĐ3 | F42: Trigger + view mảng C (vd: chặn kê thuốc bệnh nhân dị ứng; v_ho_so_tom_tat) | G42: Đăng Khoa | H42: Hữu Khoa | I42: sql/C_trigger_view.sql | J42: Chưa bắt đầu | K42: 0
A43: T39 | B43: 9 | C43: =IF('Tổng quan'!$B$4="","",'Tổng quan'!$B$4+(B43-1)*7) | D43: =IF('Tổng quan'!$B$4="","",C43+6) | E43: GĐ3 | F43: Dữ liệu mẫu (seed.sql): mỗi người viết cho mảng mình, Đăng Khoa gộp và đảm bảo đủ để truy vấn có kết quả | G43: Đăng Khoa | H43: Cả nhóm | I43: sql/seed.sql | J43: Chưa bắt đầu | K43: 0
A44: T40 | B44: 10 | C44: =IF('Tổng quan'!$B$4="","",'Tổng quan'!$B$4+(B44-1)*7) | D44: =IF('Tổng quan'!$B$4="","",C44+6) | E44: GĐ3 | F44: 4 truy vấn phức tạp mảng A (JOIN, subquery, hàm tổng hợp, GROUP BY/HAVING) | G44: Hữu Khoa | H44: Khôi | I44: sql/queries_A.sql | J44: Chưa bắt đầu | K44: 0
...

Sheet Mảng nghiệp vụ
A1: Phân chia mảng nghiệp vụ (mỗi người sở hữu end-to-end)
A2: Tên thực thể/trigger/truy vấn là đề xuất ban đầu – chốt lại ở GĐ0–GĐ1.
A4: Hạng mục | B4: A. Nhân viên y tế & Lịch làm việc (Hữu Khoa) | C4: B. Bệnh nhân & Lịch hẹn (Khôi) | D4: C. Bệnh án & Đơn thuốc (Đăng Khoa)
A5: Thực thể chính | B5: BAC_SI (lớp cha; chứng chỉ hành nghề là thuộc tính) → BAC_SI_DA_KHOA, BAC_SI_CHUYEN_KHOA CHUYEN_KHOA, CA_LAM_VIEC | C5: BENH_NHAN LICH_HEN (lớp cha; có phí khám) → KHAM_TRUC_TIEP, TU_VAN_TU_XA (nền tảng, link phiên) GIAY_CHUYEN_KHOA | D5: LAN_KHAM, CHAN_DOAN (mã ICD-10), DON_THUOC THUOC, HOAT_CHAT; KÊ (đơn – thuốc), CHỨA (thuốc – hoạt chất), DI_UNG (bệnh nhân – hoạt chất) Hồ sơ bệnh án = view tổng hợp
A6: Điểm EER / khó khăn | B6: Phân lớp disjoint + total cho BAC_SI {Đa khoa, Chuyên khoa}; lý giải chọn phương án ánh xạ 8A/8B/8C | C6: Phân lớp hình thức khám (trực tiếp / từ xa); vòng đời trạng thái lịch hẹn: Đã đặt → Đã xác nhận → Hoàn thành / Hủy / Vắng mặt | D6: Toàn vẹn bệnh án: đơn thuốc chỉ gắn lần khám đã hoàn thành, do bác sĩ lập; không xóa bệnh án (chỉ đánh dấu)
A7: Quy tắc nghiệp vụ gợi ý | B7: • Mỗi bác sĩ thuộc đúng 1 loại: đa khoa hoặc chuyên khoa • BS chuyên khoa thuộc đúng 1 chuyên khoa • Chứng chỉ hành nghề phải còn hạn mới được xếp ca • Ca làm việc của 1 bác sĩ không chồng giờ | C7: • Lịch hẹn nằm trong ca làm việc của bác sĩ • 1 bác sĩ, 1 bệnh nhân không có 2 lịch hẹn trùng giờ • Khám chuyên khoa cần giấy chuyển từ BS đa khoa (trừ tái khám) • Tư vấn từ xa bắt buộc có link phiên | D7: • Không kê thuốc chứa hoạt chất bệnh nhân dị ứng • Số lượng, liều dùng > 0 • Mỗi lần khám có ≥1 chẩn đoán trước khi kê đơn • Bệnh nhân chỉ xem hồ sơ của chính mình
A8: Trigger (≥1) | B8: trg_kiem_tra_chung_chi – chặn xếp ca khi chứng chỉ hết hạn trg_bao_ve_ca_lam_viec – chặn sửa/hủy ca làm lịch hẹn rơi ra ngoài ca | C8: trg_lich_hen_hop_le – lịch hẹn phải trong ca, không trùng giờ trg_trang_thai_lich_hen – chỉ cho chuyển trạng thái hợp lệ | D8: trg_chan_thuoc_di_ung – chặn kê thuốc dị ứng trg_lan_kham_hoan_thanh – lần khám chỉ cho lịch HOAN_THANH trg_khong_xoa_benh_an – chặn DELETE bệnh án
A9: View (≥1) | B9: v_lich_truc_bac_si | C9: v_lich_hen_hom_nay | D9: v_ho_so_tom_tat_benh_nhan
A10: 4 truy vấn phức tạp | B10: 1. BS chuyên khoa còn ca trống tuần tới theo chuyên khoa 2. Tổng giờ làm việc/tháng mỗi bác sĩ (GROUP BY, HAVING) 3. Bác sĩ chưa được xếp ca nào (NOT EXISTS) 4. Chứng chỉ hết hạn trong 30 ngày tới | C10: 1. Tỷ lệ hủy/vắng mặt theo bác sĩ 2. Doanh thu theo chuyên khoa theo tháng 3. Bệnh nhân khám > 3 lần trong 6 tháng (subquery) 4. Khung giờ đông nhất / tỷ lệ khám từ xa so với trực tiếp | D10: 1. Top 10 thuốc được kê nhiều nhất theo quý 2. Bệnh nhân có chẩn đoán X chưa tái khám sau 30 ngày 3. Lịch sử khám đầy đủ của 1 bệnh nhân (JOIN 5+ bảng) 4. Bác sĩ có số thuốc trung bình/đơn cao hơn mức chung
A11: Màn hình UI | B11: Danh sách bác sĩ theo chuyên khoa; lịch làm việc theo tuần | C11: Đặt lịch hẹn (hiện lỗi khi trùng giờ); danh sách lịch hẹn theo ngày | D11: Tạo lần khám + kê đơn (hiện cảnh báo dị ứng); xem bệnh án
A12: Phần báo cáo phụ trách | B12: 2.1 (gộp), 2.2 (gộp), 3, 4.1 | C12: 1, 1.1, 1.2 (gộp), tóm tắt, tài liệu tham khảo | D12: 2.3 (gộp), 4.2, 5.1, 5.2

Sheet Viết báo cáo
A1: Phân công viết báo cáo theo mẫu INT1313
A2: Người viết chính chịu trách nhiệm gộp và thống nhất văn phong; người đóng góp gửi nội dung mảng mình.
A4: Mục | B4: Nội dung | C4: Viết chính | D4: Đóng góp | E4: Phiên bản nộp | F4: Tuần hạn | G4: Trạng thái
A5: – | B5: Giới thiệu tóm tắt (~200 từ) | C5: Khôi | D5: Hữu Khoa, Đăng Khoa | E5: v1 → cập nhật mỗi bản | F5: 12 | G5: Hoàn thành
A6: 1 | B6: Giới thiệu đồ án & phạm vi (ISO/IEC/IEEE 29148) | C6: Khôi | D6: – | E6: v1 | F6: 2 | G6: Hoàn thành
A7: 1.1 | B7: Mục tiêu hệ thống | C7: Khôi | D7: Hữu Khoa | E7: v1 | F7: 2 | G7: Hoàn thành
A8: 1.2 | B8: Quy tắc & ràng buộc nghiệp vụ | C8: Khôi | D8: Cả 3 (BR mảng mình) | E8: v1 | F8: 2 | G8: Hoàn thành
A9: 2 | B9: Giới thiệu thiết kế CSDL | C9: Hữu Khoa | D9: – | E9: v2.1 | F9: 4 | G9: Hoàn thành
A10: 2.1 | B10: Mô hình khái niệm (ER/EER) | C10: Hữu Khoa | D10: Cả 3 (mảng mình) | E10: v2.1 | F10: 4 | G10: Hoàn thành
A11: 2.2 | B11: Ánh xạ lược đồ logic | C11: Hữu Khoa | D11: Cả 3 (mảng mình) | E11: v2.2 | F11: 8 | G11: Đang làm
A12: 2.3 | B12: Kiểm tra chuẩn hóa 1NF → 3NF/BCNF | C12: Đăng Khoa | D12: Cả 3 (mảng mình) | E12: v2.2 | F12: 8 | G12: Đang làm
A13: 3 | B13: Từ điển dữ liệu (ISO/IEC 11179) | C13: Hữu Khoa | D13: Cả 3 (bảng mình) | E13: v2.2 | F13: 8 | G13: Đang làm
A14: 4.1 | B14: DDL: bảng, view, index, trigger | C14: Hữu Khoa | D14: Cả 3 (mảng mình) | E14: v3 | F14: 10 | G14: Chưa bắt đầu
A15: 4.2 | B15: Truy vấn nâng cao & kiểm thử hiệu năng | C15: Đăng Khoa | D15: Cả 3 (4 truy vấn/người) | E15: v3 | F15: 10 | G15: Chưa bắt đầu
A16: 5.1 | B16: Các bài kiểm tra ràng buộc | C16: Đăng Khoa | D16: Cả 3 (test mảng mình) | E16: v3 | F16: 10 | G16: Chưa bắt đầu
... A19: Slide | B19: Slide thuyết trình + kịch bản demo | C19: Khôi | D19: Cả 3 (slide mảng mình) | E19: – | F19: 11 | G19: Chưa bắt đầu

Sheet Báo cáo tuần
A1: Nhật ký tiến độ hàng tuần
A2: Mỗi thành viên thêm 1 dòng/tuần trước buổi họp. Dòng 5 là ví dụ mẫu – xóa hoặc giữ làm tham khảo.
A4: Tuần | B4: Ngày | C4: Thành viên | D4: Đã làm tuần này (mã việc) | E4: Kế hoạch tuần sau | F4: Vướng mắc / cần hỗ trợ | G4: Link sản phẩm (commit, file)
A5: 1 | C5: Hữu Khoa | D5: T02: tạo repo, README cài PostgreSQL. T04: khảo sát 2 phòng khám, ghi 12 quy tắc ca trực | E5: T07: viết BR-A01…A10 | F5: Chưa rõ điều dưỡng có cần phân lớp riêng không – hỏi GV | G5: github.com/…/commit/…
A6: 1 | B6: 46303 | C6: Khôi | D6: T02: cấu trúc repo, README cài PostgreSQL 16 + draw.io, gỡ file nhạy cảm khỏi repo public T03: khảo sát mảng B (Medpro, YouMed, BookingCare), đề xuất 6 thực thể T08: BR-B01…B11 kèm cơ chế và cách kiểm chứng; chạy thử EXCLUDE chống trùng lịch trên PG16 T06: báo cáo mục 1 và 1.1 (MT-01…07) | E6: T10: gộp mục 1.2 (BR mảng A, C), review chéo, nộp báo cáo v1 | F6: Hữu Khoa: chốt phương án ánh xạ lớp bác sĩ đa khoa (ảnh hưởng BR-B09) Cả nhóm: đồng ý bỏ BAO_HIEM_Y_TE khỏi mảng B Đăng Khoa: giữ số hiệu BR-C01…C05 vì MT-04, MT-05 đang tham chiếu | G6: github.com/khoiln218/telemedicine README.md docs/khao-sat/T03_KhaoSat_MangB.md docs/br/T08_BR_MangB.md docs/…_v0.docx (mục 1, 1.1)
A7: 2 | B7: 46309 | C7: Khôi | D7: T10: review chéo BR mảng A (BR_MangA.md) và C (T09), ghi điểm cần sửa vào kế hoạch; gộp mục 1.2 + 1.2.4 vào báo cáo v1 (docx đổi tên _v1) | E7: T10: chốt 1.2 với Hữu Khoa, Đăng Khoa, nộp v1 + báo cáo tiến độ. T12: vẽ ER/EER mảng B | F7: Hữu Khoa: xác nhận BR-A01…A08 theo review (giữ số hiệu v0), review BR mảng B Đăng Khoa: sửa T09 theo review | G7: docs/INT1313_TX_G5_DeTai05_Telemedicine_v1.docx docs/KeHoach_G5_Telemedicine.xlsx nhánh member/Khoi
A8: 3 | B8: 46314 | C8: Khôi | D8: T13, T15: review ERD và truy vết mảng C (PR #4), sửa theo review Đơn giản hóa phạm vi A, B, C theo đề bài: bỏ NHAN_VIEN_Y_TE/DIEU_DUONG/LE_TAN, CO_SO_KHAM, HOA_DON, HO_SO_BENH_AN T03, T04, T05: khảo sát theo ISO/IEC/IEEE 29148 (T04 soạn thay Hữu Khoa) T07, T08, T09: quy tắc nghiệp vụ theo Business Rules Manifesto/SBVR; mảng B còn BR-B01…B07 T11, T12, T13, T14: ERD A, B, C và ERD tổng theo ký hiệu Chen/Elmasri (ERD A, ERD tổng soạn thay Hữu Khoa) T15: ma trận truy vết hai chiều A, B, C T17: báo cáo v2.1 có Giới thiệu tóm tắt, mục 1, 1.2, 2, 2.1 hoàn chỉnh, định dạng theo mẫu | E8: T17: review chéo, điền ngày nộp, nộp v2.1 + báo cáo tiến độ | F8: Hữu Khoa: review T04, T07, T11, T14 do Khôi soạn Hữu Khoa, Đăng Khoa: xác nhận phần thu gọn mảng A, C Cả nhóm: chốt tên khóa ma_bac_si, ma_chuyen_khoa; phương án ánh xạ phân lớp bác sĩ (8A/8B/8C) | G8: nhánh Khoi docs/khao-sat/T03, T04, T05 docs/br/T07, T08, T09 erd/A, B, C, ERD_tong (.drawio, .png) docs/traceability/T15_Traceability.md docs/INT1313_TX_G5_DeTai05_Telemedicine_v2.1.docx
A9: 4 | B9: 46322 | C9: Khôi | D9: T20: ánh xạ mảng B sang lược đồ quan hệ (Elmasri bước 1–8): 4 bảng, PK/FK, UNIQUE; phân lớp LICH_HEN chọn 8C; truy vết ERD → lược đồ, quy tắc còn lại cho cài đặt T24: FD và khóa ứng viên 4 bảng mảng B, ghi FD đã xét và loại; nêu 2 điểm cho T27/T30 (FD có điều kiện trên cột UNIQUE cho phép NULL; TAI_KHOAN.vai_tro trùng NHAN_VIEN.loai_nv) T27: chứng minh 1NF → BCNF 4 bảng mảng B, không phải tách; ghi các thiết kế đã tránh vi phạm 3NF T33 (làm sớm): DDL mảng B, chạy thử 17 ca vi phạm trên PG16 đều bị chặn T37 (làm sớm): 4 trigger + view v_lich_hen_hom_nay mảng B, chạy thử 17 ca vi phạm đều bị chặn T30 (phần B): đối chiếu T20, T24, T27 với DDL, trigger; sửa T20 (FK kép giấy – bệnh nhân); lập danh sách lỗi, bảng quy tắc → cơ chế T41 (làm sớm): 4 truy vấn mảng B, kiểm chứng trên dữ liệu thử đi qua trigger T31 (nháp v2.2): điền phần B mục 2.2, 2.3, 3 vào báo cáo (đổi tên file sang _v2.2); bổ sung CHECK email, ngày sinh cho benh_nhan theo 1.2.4 | E9: T21: review ánh xạ mảng C. T29: điền từ điển dữ liệu bảng mảng B | F9: Hữu Khoa: chốt phương án ánh xạ BAC_SI (8A hay 8C) ở T19 – ảnh hưởng FK ma_bac_si_lap → BAC_SI_DA_KHOA; review T20 Đăng Khoa: review T24; chốt cách trình bày FD có điều kiện ở T22 Đăng Khoa: review T27; T30 chốt TAI_KHOAN.vai_tro (giữ hay suy từ loai_nv) Hữu Khoa: T18 chốt kiểu khóa (INTEGER identity), giá trị loai_nv trùng vai_tro (QUAN_TRI_NHAN_SU, QUAN_TRI_TAI_KHOAN, QUAN_TRI_DANH_MUC, BAC_SI, LE_TAN); review T33 Đăng Khoa: review T37; T39 seed phải thêm lịch hẹn ở DA_DAT rồi UPDATE, lịch nằm trong ca, lịch chuyên khoa có giấy hoặc tái khám Cả nhóm: họp chốt C1 (TAI_KHOAN.vai_tro trùng loai_nv, BR-B10 đổi vai trò mâu thuẫn BR-A09) Hữu Khoa, Đăng Khoa: điền phần A, C vào docs/…_v2.2.docx (chỗ chữ xám); Hữu Khoa vẽ Hình 2.2 lược đồ quan hệ | G9: docs/5_anh-xa/T20_AnhXa_MangB.md commit 78857c7, nhánh Khoi docs/6_chuan-hoa/T24_FD_MangB.md docs/6_chuan-hoa/T27_ChuanHoa_MangB.md sql/B_schema.sql sql/B_trigger_view.sql docs/6_chuan-hoa/T30_ReviewCheo.md sql/queries_B.sql docs/INT1313_TX_G5_DeTai05_Telemedicine_v2.2.docx

Sheet Thống kê
A1: Thống kê tiến độ & mức đóng góp
A2: Tự tính từ sheet 'Kế hoạch' – không cần nhập.
A4: Thành viên | B4: Số việc phụ trách | C4: Hoàn thành | D4: Đang làm | E4: Trễ hạn | F4: % việc hoàn thành | G4: % hoàn thành TB | H4: Số việc review
A5: Khôi | B5: =COUNTIF('Kế hoạch'!$G$5:$G$109,A5) -> 19 | C5: =COUNTIFS('Kế hoạch'!$G$5:$G$109,A5,'Kế hoạch'!$J$5:$J$109,"Hoàn thành") -> 12 | D5: =COUNTIFS('Kế hoạch'!$G$5:$G$109,A5,'Kế hoạch'!$J$5:$J$109,"Đang làm") -> 2 | E5: =COUNTIFS('Kế hoạch'!$G$5:$G$109,A5,'Kế hoạch'!$J$5:$J$109,"Trễ hạn") -> 0 | F5: =IFERROR(C5/B5,0) -> 0.63157895 | G5: =IFERROR(AVERAGEIF('Kế hoạch'!$G$5:$G$109,A5,'Kế hoạch'!$K$5:$K$109),0) -> 0.68947368 | H5: =COUNTIF('Kế hoạch'!$H$5:$H$109,A5) -> 10
A6: Hữu Khoa | B6: =COUNTIF('Kế hoạch'!$G$5:$G$109,A6) -> 16 | C6: =COUNTIFS('Kế hoạch'!$G$5:$G$109,A6,'Kế hoạch'!$J$5:$J$109,"Hoàn thành") -> 5 | D6: =COUNTIFS('Kế hoạch'!$G$5:$G$109,A6,'Kế hoạch'!$J$5:$J$109,"Đang làm") -> 0 | E6: =COUNTIFS('Kế hoạch'!$G$5:$G$109,A6,'Kế hoạch'!$J$5:$J$109,"Trễ hạn") -> 0 | F6: =IFERROR(C6/B6,0) -> 0.3125 | G6: =IFERROR(AVERAGEIF('Kế hoạch'!$G$5:$G$109,A6,'Kế hoạch'!$K$5:$K$109),0) -> 0.3125 | H6: =COUNTIF('Kế hoạch'!$H$5:$H$109,A6) -> 14
A7: Đăng Khoa | B7: =COUNTIF('Kế hoạch'!$G$5:$G$109,A7) -> 17 | C7: =COUNTIFS('Kế hoạch'!$G$5:$G$109,A7,'Kế hoạch'!$J$5:$J$109,"Hoàn thành") -> 4 | D7: =COUNTIFS('Kế hoạch'!$G$5:$G$109,A7,'Kế hoạch'!$J$5:$J$109,"Đang làm") -> 1 | E7: =COUNTIFS('Kế hoạch'!$G$5:$G$109,A7,'Kế hoạch'!$J$5:$J$109,"Trễ hạn") -> 0 | F7: =IFERROR(C7/B7,0) -> 0.23529412 | G7: =IFERROR(AVERAGEIF('Kế hoạch'!$G$5:$G$109,A7,'Kế hoạch'!$K$5:$K$109),0) -> 0.25294118 | H7: =COUNTIF('Kế hoạch'!$H$5:$H$109,A7) -> 13
A8: Cả nhóm | B8: =COUNTIF('Kế hoạch'!$G$5:$G$109,A8) -> 3 | C8: =COUNTIFS('Kế hoạch'!$G$5:$G$109,A8,'Kế hoạch'!$J$5:$J$109,"Hoàn thành") -> 0 | D8: =COUNTIFS('Kế hoạch'!$G$5:$G$109,A8,'Kế hoạch'!$J$5:$J$109,"Đang làm") -> 0 | E8: =COUNTIFS('Kế hoạch'!$G$5:$G$109,A8,'Kế hoạch'!$J$5:$J$109,"Trễ hạn") -> 0 | F8: =IFERROR(C8/B8,0) -> 0 | G8: =IFERROR(AVERAGEIF('Kế hoạch'!$G$5:$G$109,A8,'Kế hoạch'!$K$5:$K$109),0) -> 0 | H8: =COUNTIF('Kế hoạch'!$H$5:$H$109,A8) -> 18
A9: Tổng | B9: =SUM(B5:B8) -> 55 | C9: =SUM(C5:C8) -> 21 | D9: =SUM(D5:D8) -> 3 | E9: =SUM(E5:E8) -> 0 | F9: =IFERROR(C9/B9,0) -> 0.38181818 | G9: =IFERROR(AVERAGE('Kế hoạch'!$K$5:$K$109),0) -> 0.40727273 | H9: =SUM(H5:H8) -> 55
A12: Tiến độ theo giai đoạn
A13: Giai đoạn | B13: Số việc | C13: Hoàn thành | D13: % hoàn thành
A14: GĐ0 | B14: =COUNTIF('Kế hoạch'!$E$5:$E$109,A14) -> 10 | C14: =COUNTIFS('Kế hoạch'!$E$5:$E$109,A14,'Kế hoạch'!$J$5:$J$109,"Hoàn thành") -> 8 | D14: =IFERROR(C14/B14,0) -> 0.8
A15: GĐ1 | B15: =COUNTIF('Kế hoạch'!$E$5:$E$109,A15) -> 7 | C15: =COUNTIFS('Kế hoạch'!$E$5:$E$109,A15,'Kế hoạch'!$J$5:$J$109,"Hoàn thành") -> 7 | D15: =IFERROR(C15/B15,0) -> 1
A16: GĐ2 | B16: =COUNTIF('Kế hoạch'!$E$5:$E$109,A16) -> 14 | C16: =COUNTIFS('Kế hoạch'!$E$5:$E$109,A16,'Kế hoạch'!$J$5:$J$109,"Hoàn thành") -> 3 | D16: =IFERROR(C16/B16,0) -> 0.21428571
A17: GĐ3 | B17: =COUNTIF('Kế hoạch'!$E$5:$E$109,A17) -> 15 | C17: =COUNTIFS('Kế hoạch'!$E$5:$E$109,A17,'Kế hoạch'!$J$5:$J$109,"Hoàn thành") -> 3 | D17: =IFERROR(C17/B17,0) -> 0.2
A18: GĐ4 | B18: =COUNTIF('Kế hoạch'!$E$5:$E$109,A18) -> 9 | C18: =COUNTIFS('Kế hoạch'!$E$5:$E$109,A18,'Kế hoạch'!$J$5:$J$109,"Hoàn thành") -> 0 | D18: =IFERROR(C18/B18,0) -> 0
A20: Ghi chú: việc của 'Cả nhóm' tính riêng; dùng bảng này cùng sheet 'Báo cáo tuần' làm căn cứ cho đánh giá chéo (15% điểm cá nhân).
